{
  "nbformat": 4,
  "nbformat_minor": 0,
  "metadata": {
    "colab": {
      "name": "Project.ipynb",
      "provenance": [],
      "collapsed_sections": [],
      "mount_file_id": "1HgQrtNIFSKIb9M9xFATo9GfBeiTr-LPI",
      "authorship_tag": "ABX9TyNkIdops70IMfn/buCP9CJi"
    },
    "kernelspec": {
      "name": "python3",
      "display_name": "Python 3"
    }
  },
  "cells": [
    {
      "cell_type": "code",
      "metadata": {
        "colab": {
          "base_uri": "https://localhost:8080/"
        },
        "id": "Qj9pcig6fc8P",
        "outputId": "d983db92-3c6f-45b4-8277-36dd718be17c"
      },
      "source": [
        "!git clone https://github.com/eragonruan/text-detection-ctpn"
      ],
      "execution_count": null,
      "outputs": [
        {
          "output_type": "stream",
          "text": [
            "fatal: could not create work tree dir 'text-detection-ctpn': Operation not supported\n"
          ],
          "name": "stdout"
        }
      ]
    },
    {
      "cell_type": "code",
      "metadata": {
        "colab": {
          "base_uri": "https://localhost:8080/"
        },
        "id": "rJoZ3Akqfkel",
        "outputId": "a1868ff3-fabe-4668-8eb5-58976eed72e2"
      },
      "source": [
        "%cd text-detection-ctpn/utils/bbox/"
      ],
      "execution_count": null,
      "outputs": [
        {
          "output_type": "stream",
          "text": [
            "/content/text-detection-ctpn/utils/bbox/text-detection-ctpn/utils/bbox/text-detection-ctpn/utils/bbox\n"
          ],
          "name": "stdout"
        }
      ]
    },
    {
      "cell_type": "code",
      "metadata": {
        "id": "h3ik7V_mfsMx"
      },
      "source": [
        "!chmod +x make.sh"
      ],
      "execution_count": null,
      "outputs": []
    },
    {
      "cell_type": "code",
      "metadata": {
        "colab": {
          "base_uri": "https://localhost:8080/"
        },
        "id": "1uyaYO7-fwP1",
        "outputId": "cf370234-322b-4231-e751-b0a7f0952567"
      },
      "source": [
        "!./make.sh"
      ],
      "execution_count": null,
      "outputs": [
        {
          "output_type": "stream",
          "text": [
            "running install\n",
            "running build\n",
            "running build_ext\n",
            "building 'bbox' extension\n",
            "creating build\n",
            "creating build/temp.linux-x86_64-3.7\n",
            "x86_64-linux-gnu-gcc -pthread -Wno-unused-result -Wsign-compare -DNDEBUG -g -fwrapv -O2 -Wall -g -fdebug-prefix-map=/build/python3.7-a56wZI/python3.7-3.7.10=. -fstack-protector-strong -Wformat -Werror=format-security -g -fdebug-prefix-map=/build/python3.7-a56wZI/python3.7-3.7.10=. -fstack-protector-strong -Wformat -Werror=format-security -Wdate-time -D_FORTIFY_SOURCE=2 -fPIC -I/usr/local/lib/python3.7/dist-packages/numpy/core/include -I/usr/include/python3.7m -c bbox.c -o build/temp.linux-x86_64-3.7/bbox.o\n",
            "In file included from \u001b[01m\u001b[K/usr/local/lib/python3.7/dist-packages/numpy/core/include/numpy/ndarraytypes.h:1822:0\u001b[m\u001b[K,\n",
            "                 from \u001b[01m\u001b[K/usr/local/lib/python3.7/dist-packages/numpy/core/include/numpy/ndarrayobject.h:12\u001b[m\u001b[K,\n",
            "                 from \u001b[01m\u001b[K/usr/local/lib/python3.7/dist-packages/numpy/core/include/numpy/arrayobject.h:4\u001b[m\u001b[K,\n",
            "                 from \u001b[01m\u001b[Kbbox.c:283\u001b[m\u001b[K:\n",
            "\u001b[01m\u001b[K/usr/local/lib/python3.7/dist-packages/numpy/core/include/numpy/npy_1_7_deprecated_api.h:17:2:\u001b[m\u001b[K \u001b[01;35m\u001b[Kwarning: \u001b[m\u001b[K#warning \"Using deprecated NumPy API, disable it with \" \"#define NPY_NO_DEPRECATED_API NPY_1_7_API_VERSION\" [\u001b[01;35m\u001b[K-Wcpp\u001b[m\u001b[K]\n",
            " #\u001b[01;35m\u001b[Kwarning\u001b[m\u001b[K \"Using deprecated NumPy API, disable it with \" \\\n",
            "  \u001b[01;35m\u001b[K^~~~~~~\u001b[m\u001b[K\n",
            "In file included from \u001b[01m\u001b[K/usr/local/lib/python3.7/dist-packages/numpy/core/include/numpy/ndarrayobject.h:21:0\u001b[m\u001b[K,\n",
            "                 from \u001b[01m\u001b[K/usr/local/lib/python3.7/dist-packages/numpy/core/include/numpy/arrayobject.h:4\u001b[m\u001b[K,\n",
            "                 from \u001b[01m\u001b[Kbbox.c:283\u001b[m\u001b[K:\n",
            "\u001b[01m\u001b[K/usr/local/lib/python3.7/dist-packages/numpy/core/include/numpy/__multiarray_api.h:1463:1:\u001b[m\u001b[K \u001b[01;35m\u001b[Kwarning: \u001b[m\u001b[K‘\u001b[01m\u001b[K_import_array\u001b[m\u001b[K’ defined but not used [\u001b[01;35m\u001b[K-Wunused-function\u001b[m\u001b[K]\n",
            " \u001b[01;35m\u001b[K_import_array\u001b[m\u001b[K(void)\n",
            " \u001b[01;35m\u001b[K^~~~~~~~~~~~~\u001b[m\u001b[K\n",
            "creating build/lib.linux-x86_64-3.7\n",
            "x86_64-linux-gnu-gcc -pthread -shared -Wl,-O1 -Wl,-Bsymbolic-functions -Wl,-Bsymbolic-functions -Wl,-z,relro -Wl,-Bsymbolic-functions -Wl,-z,relro -g -fdebug-prefix-map=/build/python3.7-a56wZI/python3.7-3.7.10=. -fstack-protector-strong -Wformat -Werror=format-security -Wdate-time -D_FORTIFY_SOURCE=2 build/temp.linux-x86_64-3.7/bbox.o -o build/lib.linux-x86_64-3.7/bbox.cpython-37m-x86_64-linux-gnu.so\n",
            "running install_lib\n",
            "copying build/lib.linux-x86_64-3.7/bbox.cpython-37m-x86_64-linux-gnu.so -> /usr/local/lib/python3.7/dist-packages\n",
            "running install_egg_info\n",
            "Removing /usr/local/lib/python3.7/dist-packages/UNKNOWN-0.0.0.egg-info\n",
            "Writing /usr/local/lib/python3.7/dist-packages/UNKNOWN-0.0.0.egg-info\n",
            "running install\n",
            "running build\n",
            "running build_ext\n",
            "building 'nms' extension\n",
            "x86_64-linux-gnu-gcc -pthread -Wno-unused-result -Wsign-compare -DNDEBUG -g -fwrapv -O2 -Wall -g -fdebug-prefix-map=/build/python3.7-a56wZI/python3.7-3.7.10=. -fstack-protector-strong -Wformat -Werror=format-security -g -fdebug-prefix-map=/build/python3.7-a56wZI/python3.7-3.7.10=. -fstack-protector-strong -Wformat -Werror=format-security -Wdate-time -D_FORTIFY_SOURCE=2 -fPIC -I/usr/local/lib/python3.7/dist-packages/numpy/core/include -I/usr/include/python3.7m -c nms.c -o build/temp.linux-x86_64-3.7/nms.o\n",
            "In file included from \u001b[01m\u001b[K/usr/local/lib/python3.7/dist-packages/numpy/core/include/numpy/ndarraytypes.h:1822:0\u001b[m\u001b[K,\n",
            "                 from \u001b[01m\u001b[K/usr/local/lib/python3.7/dist-packages/numpy/core/include/numpy/ndarrayobject.h:12\u001b[m\u001b[K,\n",
            "                 from \u001b[01m\u001b[K/usr/local/lib/python3.7/dist-packages/numpy/core/include/numpy/arrayobject.h:4\u001b[m\u001b[K,\n",
            "                 from \u001b[01m\u001b[Knms.c:283\u001b[m\u001b[K:\n",
            "\u001b[01m\u001b[K/usr/local/lib/python3.7/dist-packages/numpy/core/include/numpy/npy_1_7_deprecated_api.h:17:2:\u001b[m\u001b[K \u001b[01;35m\u001b[Kwarning: \u001b[m\u001b[K#warning \"Using deprecated NumPy API, disable it with \" \"#define NPY_NO_DEPRECATED_API NPY_1_7_API_VERSION\" [\u001b[01;35m\u001b[K-Wcpp\u001b[m\u001b[K]\n",
            " #\u001b[01;35m\u001b[Kwarning\u001b[m\u001b[K \"Using deprecated NumPy API, disable it with \" \\\n",
            "  \u001b[01;35m\u001b[K^~~~~~~\u001b[m\u001b[K\n",
            "In file included from \u001b[01m\u001b[K/usr/local/lib/python3.7/dist-packages/numpy/core/include/numpy/ndarrayobject.h:21:0\u001b[m\u001b[K,\n",
            "                 from \u001b[01m\u001b[K/usr/local/lib/python3.7/dist-packages/numpy/core/include/numpy/arrayobject.h:4\u001b[m\u001b[K,\n",
            "                 from \u001b[01m\u001b[Knms.c:283\u001b[m\u001b[K:\n",
            "\u001b[01m\u001b[K/usr/local/lib/python3.7/dist-packages/numpy/core/include/numpy/__multiarray_api.h:1463:1:\u001b[m\u001b[K \u001b[01;35m\u001b[Kwarning: \u001b[m\u001b[K‘\u001b[01m\u001b[K_import_array\u001b[m\u001b[K’ defined but not used [\u001b[01;35m\u001b[K-Wunused-function\u001b[m\u001b[K]\n",
            " \u001b[01;35m\u001b[K_import_array\u001b[m\u001b[K(void)\n",
            " \u001b[01;35m\u001b[K^~~~~~~~~~~~~\u001b[m\u001b[K\n",
            "x86_64-linux-gnu-gcc -pthread -shared -Wl,-O1 -Wl,-Bsymbolic-functions -Wl,-Bsymbolic-functions -Wl,-z,relro -Wl,-Bsymbolic-functions -Wl,-z,relro -g -fdebug-prefix-map=/build/python3.7-a56wZI/python3.7-3.7.10=. -fstack-protector-strong -Wformat -Werror=format-security -Wdate-time -D_FORTIFY_SOURCE=2 build/temp.linux-x86_64-3.7/nms.o -o build/lib.linux-x86_64-3.7/nms.cpython-37m-x86_64-linux-gnu.so\n",
            "running install_lib\n",
            "copying build/lib.linux-x86_64-3.7/nms.cpython-37m-x86_64-linux-gnu.so -> /usr/local/lib/python3.7/dist-packages\n",
            "running install_egg_info\n",
            "Removing /usr/local/lib/python3.7/dist-packages/UNKNOWN-0.0.0.egg-info\n",
            "Writing /usr/local/lib/python3.7/dist-packages/UNKNOWN-0.0.0.egg-info\n"
          ],
          "name": "stdout"
        }
      ]
    },
    {
      "cell_type": "code",
      "metadata": {
        "colab": {
          "base_uri": "https://localhost:8080/"
        },
        "id": "WkdUT02PgKTE",
        "outputId": "fa55e210-09df-4691-8f4a-064c8e46e201"
      },
      "source": [
        "%cd .."
      ],
      "execution_count": 61,
      "outputs": [
        {
          "output_type": "stream",
          "text": [
            "/content/text-detection-ctpn\n"
          ],
          "name": "stdout"
        }
      ]
    },
    {
      "cell_type": "code",
      "metadata": {
        "id": "8ylIXx4Cif5k",
        "colab": {
          "base_uri": "https://localhost:8080/"
        },
        "outputId": "baac2275-d4dc-4b25-ba0c-b49f10879189"
      },
      "source": [
        "len(os.listdir('data/dataset/mlt/image/'))"
      ],
      "execution_count": 48,
      "outputs": [
        {
          "output_type": "execute_result",
          "data": {
            "text/plain": [
              "704"
            ]
          },
          "metadata": {
            "tags": []
          },
          "execution_count": 48
        }
      ]
    },
    {
      "cell_type": "code",
      "metadata": {
        "id": "kp9-W99m3PEe",
        "colab": {
          "base_uri": "https://localhost:8080/"
        },
        "outputId": "d698d602-8ddf-4b08-de5a-a24519a58088"
      },
      "source": [
        "!pip install tensorflow==1.14"
      ],
      "execution_count": 52,
      "outputs": [
        {
          "output_type": "stream",
          "text": [
            "Collecting tensorflow==1.14\n",
            "\u001b[?25l  Downloading https://files.pythonhosted.org/packages/f4/28/96efba1a516cdacc2e2d6d081f699c001d414cc8ca3250e6d59ae657eb2b/tensorflow-1.14.0-cp37-cp37m-manylinux1_x86_64.whl (109.3MB)\n",
            "\u001b[K     |████████████████████████████████| 109.3MB 80kB/s \n",
            "\u001b[?25hRequirement already satisfied: absl-py>=0.7.0 in /usr/local/lib/python3.7/dist-packages (from tensorflow==1.14) (0.10.0)\n",
            "Requirement already satisfied: grpcio>=1.8.6 in /usr/local/lib/python3.7/dist-packages (from tensorflow==1.14) (1.32.0)\n",
            "Requirement already satisfied: google-pasta>=0.1.6 in /usr/local/lib/python3.7/dist-packages (from tensorflow==1.14) (0.2.0)\n",
            "Requirement already satisfied: numpy<2.0,>=1.14.5 in /usr/local/lib/python3.7/dist-packages (from tensorflow==1.14) (1.19.5)\n",
            "Collecting tensorflow-estimator<1.15.0rc0,>=1.14.0rc0\n",
            "\u001b[?25l  Downloading https://files.pythonhosted.org/packages/3c/d5/21860a5b11caf0678fbc8319341b0ae21a07156911132e0e71bffed0510d/tensorflow_estimator-1.14.0-py2.py3-none-any.whl (488kB)\n",
            "\u001b[K     |████████████████████████████████| 491kB 15.7MB/s \n",
            "\u001b[?25hRequirement already satisfied: astor>=0.6.0 in /usr/local/lib/python3.7/dist-packages (from tensorflow==1.14) (0.8.1)\n",
            "Requirement already satisfied: termcolor>=1.1.0 in /usr/local/lib/python3.7/dist-packages (from tensorflow==1.14) (1.1.0)\n",
            "Requirement already satisfied: protobuf>=3.6.1 in /usr/local/lib/python3.7/dist-packages (from tensorflow==1.14) (3.12.4)\n",
            "Requirement already satisfied: keras-preprocessing>=1.0.5 in /usr/local/lib/python3.7/dist-packages (from tensorflow==1.14) (1.1.2)\n",
            "Collecting tensorboard<1.15.0,>=1.14.0\n",
            "\u001b[?25l  Downloading https://files.pythonhosted.org/packages/91/2d/2ed263449a078cd9c8a9ba50ebd50123adf1f8cfbea1492f9084169b89d9/tensorboard-1.14.0-py3-none-any.whl (3.1MB)\n",
            "\u001b[K     |████████████████████████████████| 3.2MB 28.6MB/s \n",
            "\u001b[?25hRequirement already satisfied: six>=1.10.0 in /usr/local/lib/python3.7/dist-packages (from tensorflow==1.14) (1.15.0)\n",
            "Requirement already satisfied: wheel>=0.26 in /usr/local/lib/python3.7/dist-packages (from tensorflow==1.14) (0.36.2)\n",
            "Requirement already satisfied: gast>=0.2.0 in /usr/local/lib/python3.7/dist-packages (from tensorflow==1.14) (0.3.3)\n",
            "Collecting keras-applications>=1.0.6\n",
            "\u001b[?25l  Downloading https://files.pythonhosted.org/packages/71/e3/19762fdfc62877ae9102edf6342d71b28fbfd9dea3d2f96a882ce099b03f/Keras_Applications-1.0.8-py3-none-any.whl (50kB)\n",
            "\u001b[K     |████████████████████████████████| 51kB 3.9MB/s \n",
            "\u001b[?25hRequirement already satisfied: wrapt>=1.11.1 in /usr/local/lib/python3.7/dist-packages (from tensorflow==1.14) (1.12.1)\n",
            "Requirement already satisfied: setuptools in /usr/local/lib/python3.7/dist-packages (from protobuf>=3.6.1->tensorflow==1.14) (54.0.0)\n",
            "Requirement already satisfied: werkzeug>=0.11.15 in /usr/local/lib/python3.7/dist-packages (from tensorboard<1.15.0,>=1.14.0->tensorflow==1.14) (1.0.1)\n",
            "Requirement already satisfied: markdown>=2.6.8 in /usr/local/lib/python3.7/dist-packages (from tensorboard<1.15.0,>=1.14.0->tensorflow==1.14) (3.3.4)\n",
            "Requirement already satisfied: h5py in /usr/local/lib/python3.7/dist-packages (from keras-applications>=1.0.6->tensorflow==1.14) (2.10.0)\n",
            "Requirement already satisfied: importlib-metadata; python_version < \"3.8\" in /usr/local/lib/python3.7/dist-packages (from markdown>=2.6.8->tensorboard<1.15.0,>=1.14.0->tensorflow==1.14) (3.7.2)\n",
            "Requirement already satisfied: typing-extensions>=3.6.4; python_version < \"3.8\" in /usr/local/lib/python3.7/dist-packages (from importlib-metadata; python_version < \"3.8\"->markdown>=2.6.8->tensorboard<1.15.0,>=1.14.0->tensorflow==1.14) (3.7.4.3)\n",
            "Requirement already satisfied: zipp>=0.5 in /usr/local/lib/python3.7/dist-packages (from importlib-metadata; python_version < \"3.8\"->markdown>=2.6.8->tensorboard<1.15.0,>=1.14.0->tensorflow==1.14) (3.4.1)\n",
            "Installing collected packages: tensorflow-estimator, tensorboard, keras-applications, tensorflow\n",
            "  Found existing installation: tensorflow-estimator 2.4.0\n",
            "    Uninstalling tensorflow-estimator-2.4.0:\n",
            "      Successfully uninstalled tensorflow-estimator-2.4.0\n",
            "  Found existing installation: tensorboard 2.4.1\n",
            "    Uninstalling tensorboard-2.4.1:\n",
            "      Successfully uninstalled tensorboard-2.4.1\n",
            "  Found existing installation: tensorflow 2.4.1\n",
            "    Uninstalling tensorflow-2.4.1:\n",
            "      Successfully uninstalled tensorflow-2.4.1\n",
            "Successfully installed keras-applications-1.0.8 tensorboard-1.14.0 tensorflow-1.14.0 tensorflow-estimator-1.14.0\n"
          ],
          "name": "stdout"
        }
      ]
    },
    {
      "cell_type": "code",
      "metadata": {
        "colab": {
          "base_uri": "https://localhost:8080/"
        },
        "id": "1Yl9Z62eh2ik",
        "outputId": "2de26cf6-9652-4ce1-9489-49f215b4c948"
      },
      "source": [
        "!python ./main/train.py"
      ],
      "execution_count": 65,
      "outputs": [
        {
          "output_type": "stream",
          "text": [
            "/usr/local/lib/python3.7/dist-packages/tensorflow/python/framework/dtypes.py:516: FutureWarning: Passing (type, 1) or '1type' as a synonym of type is deprecated; in a future version of numpy, it will be understood as (type, (1,)) / '(1,)type'.\n",
            "  _np_qint8 = np.dtype([(\"qint8\", np.int8, 1)])\n",
            "/usr/local/lib/python3.7/dist-packages/tensorflow/python/framework/dtypes.py:517: FutureWarning: Passing (type, 1) or '1type' as a synonym of type is deprecated; in a future version of numpy, it will be understood as (type, (1,)) / '(1,)type'.\n",
            "  _np_quint8 = np.dtype([(\"quint8\", np.uint8, 1)])\n",
            "/usr/local/lib/python3.7/dist-packages/tensorflow/python/framework/dtypes.py:518: FutureWarning: Passing (type, 1) or '1type' as a synonym of type is deprecated; in a future version of numpy, it will be understood as (type, (1,)) / '(1,)type'.\n",
            "  _np_qint16 = np.dtype([(\"qint16\", np.int16, 1)])\n",
            "/usr/local/lib/python3.7/dist-packages/tensorflow/python/framework/dtypes.py:519: FutureWarning: Passing (type, 1) or '1type' as a synonym of type is deprecated; in a future version of numpy, it will be understood as (type, (1,)) / '(1,)type'.\n",
            "  _np_quint16 = np.dtype([(\"quint16\", np.uint16, 1)])\n",
            "/usr/local/lib/python3.7/dist-packages/tensorflow/python/framework/dtypes.py:520: FutureWarning: Passing (type, 1) or '1type' as a synonym of type is deprecated; in a future version of numpy, it will be understood as (type, (1,)) / '(1,)type'.\n",
            "  _np_qint32 = np.dtype([(\"qint32\", np.int32, 1)])\n",
            "/usr/local/lib/python3.7/dist-packages/tensorflow/python/framework/dtypes.py:525: FutureWarning: Passing (type, 1) or '1type' as a synonym of type is deprecated; in a future version of numpy, it will be understood as (type, (1,)) / '(1,)type'.\n",
            "  np_resource = np.dtype([(\"resource\", np.ubyte, 1)])\n",
            "/usr/local/lib/python3.7/dist-packages/tensorboard/compat/tensorflow_stub/dtypes.py:541: FutureWarning: Passing (type, 1) or '1type' as a synonym of type is deprecated; in a future version of numpy, it will be understood as (type, (1,)) / '(1,)type'.\n",
            "  _np_qint8 = np.dtype([(\"qint8\", np.int8, 1)])\n",
            "/usr/local/lib/python3.7/dist-packages/tensorboard/compat/tensorflow_stub/dtypes.py:542: FutureWarning: Passing (type, 1) or '1type' as a synonym of type is deprecated; in a future version of numpy, it will be understood as (type, (1,)) / '(1,)type'.\n",
            "  _np_quint8 = np.dtype([(\"quint8\", np.uint8, 1)])\n",
            "/usr/local/lib/python3.7/dist-packages/tensorboard/compat/tensorflow_stub/dtypes.py:543: FutureWarning: Passing (type, 1) or '1type' as a synonym of type is deprecated; in a future version of numpy, it will be understood as (type, (1,)) / '(1,)type'.\n",
            "  _np_qint16 = np.dtype([(\"qint16\", np.int16, 1)])\n",
            "/usr/local/lib/python3.7/dist-packages/tensorboard/compat/tensorflow_stub/dtypes.py:544: FutureWarning: Passing (type, 1) or '1type' as a synonym of type is deprecated; in a future version of numpy, it will be understood as (type, (1,)) / '(1,)type'.\n",
            "  _np_quint16 = np.dtype([(\"quint16\", np.uint16, 1)])\n",
            "/usr/local/lib/python3.7/dist-packages/tensorboard/compat/tensorflow_stub/dtypes.py:545: FutureWarning: Passing (type, 1) or '1type' as a synonym of type is deprecated; in a future version of numpy, it will be understood as (type, (1,)) / '(1,)type'.\n",
            "  _np_qint32 = np.dtype([(\"qint32\", np.int32, 1)])\n",
            "/usr/local/lib/python3.7/dist-packages/tensorboard/compat/tensorflow_stub/dtypes.py:550: FutureWarning: Passing (type, 1) or '1type' as a synonym of type is deprecated; in a future version of numpy, it will be understood as (type, (1,)) / '(1,)type'.\n",
            "  np_resource = np.dtype([(\"resource\", np.ubyte, 1)])\n",
            "WARNING:tensorflow:From ./main/train.py:117: The name tf.app.run is deprecated. Please use tf.compat.v1.app.run instead.\n",
            "\n",
            "WARNING:tensorflow:From ./main/train.py:36: The name tf.placeholder is deprecated. Please use tf.compat.v1.placeholder instead.\n",
            "\n",
            "W0317 19:02:08.025491 140024544835456 deprecation_wrapper.py:119] From ./main/train.py:36: The name tf.placeholder is deprecated. Please use tf.compat.v1.placeholder instead.\n",
            "\n",
            "WARNING:tensorflow:From ./main/train.py:40: The name tf.get_variable is deprecated. Please use tf.compat.v1.get_variable instead.\n",
            "\n",
            "W0317 19:02:08.028405 140024544835456 deprecation_wrapper.py:119] From ./main/train.py:40: The name tf.get_variable is deprecated. Please use tf.compat.v1.get_variable instead.\n",
            "\n",
            "WARNING:tensorflow:From ./main/train.py:42: The name tf.summary.scalar is deprecated. Please use tf.compat.v1.summary.scalar instead.\n",
            "\n",
            "W0317 19:02:08.035511 140024544835456 deprecation_wrapper.py:119] From ./main/train.py:42: The name tf.summary.scalar is deprecated. Please use tf.compat.v1.summary.scalar instead.\n",
            "\n",
            "WARNING:tensorflow:From ./main/train.py:43: The name tf.train.AdamOptimizer is deprecated. Please use tf.compat.v1.train.AdamOptimizer instead.\n",
            "\n",
            "W0317 19:02:08.037091 140024544835456 deprecation_wrapper.py:119] From ./main/train.py:43: The name tf.train.AdamOptimizer is deprecated. Please use tf.compat.v1.train.AdamOptimizer instead.\n",
            "\n",
            "WARNING:tensorflow:From /content/text-detection-ctpn/nets/vgg.py:16: The name tf.variable_scope is deprecated. Please use tf.compat.v1.variable_scope instead.\n",
            "\n",
            "W0317 19:02:08.043599 140024544835456 deprecation_wrapper.py:119] From /content/text-detection-ctpn/nets/vgg.py:16: The name tf.variable_scope is deprecated. Please use tf.compat.v1.variable_scope instead.\n",
            "\n",
            "WARNING:tensorflow:Entity <bound method Conv.call of <tensorflow.python.layers.convolutional.Conv2D object at 0x7f59b1e3c390>> could not be transformed and will be executed as-is. Please report this to the AutgoGraph team. When filing the bug, set the verbosity to 10 (on Linux, `export AUTOGRAPH_VERBOSITY=10`) and attach the full output. Cause: converting <bound method Conv.call of <tensorflow.python.layers.convolutional.Conv2D object at 0x7f59b1e3c390>>: AssertionError: Bad argument number for Name: 3, expecting 4\n",
            "W0317 19:02:08.125701 140024544835456 ag_logging.py:145] Entity <bound method Conv.call of <tensorflow.python.layers.convolutional.Conv2D object at 0x7f59b1e3c390>> could not be transformed and will be executed as-is. Please report this to the AutgoGraph team. When filing the bug, set the verbosity to 10 (on Linux, `export AUTOGRAPH_VERBOSITY=10`) and attach the full output. Cause: converting <bound method Conv.call of <tensorflow.python.layers.convolutional.Conv2D object at 0x7f59b1e3c390>>: AssertionError: Bad argument number for Name: 3, expecting 4\n",
            "WARNING:tensorflow:Entity <bound method Conv.call of <tensorflow.python.layers.convolutional.Conv2D object at 0x7f59b1e3cf90>> could not be transformed and will be executed as-is. Please report this to the AutgoGraph team. When filing the bug, set the verbosity to 10 (on Linux, `export AUTOGRAPH_VERBOSITY=10`) and attach the full output. Cause: converting <bound method Conv.call of <tensorflow.python.layers.convolutional.Conv2D object at 0x7f59b1e3cf90>>: AssertionError: Bad argument number for Name: 3, expecting 4\n",
            "W0317 19:02:08.207121 140024544835456 ag_logging.py:145] Entity <bound method Conv.call of <tensorflow.python.layers.convolutional.Conv2D object at 0x7f59b1e3cf90>> could not be transformed and will be executed as-is. Please report this to the AutgoGraph team. When filing the bug, set the verbosity to 10 (on Linux, `export AUTOGRAPH_VERBOSITY=10`) and attach the full output. Cause: converting <bound method Conv.call of <tensorflow.python.layers.convolutional.Conv2D object at 0x7f59b1e3cf90>>: AssertionError: Bad argument number for Name: 3, expecting 4\n",
            "WARNING:tensorflow:Entity <bound method Pooling2D.call of <tensorflow.python.layers.pooling.MaxPooling2D object at 0x7f59b1e30f50>> could not be transformed and will be executed as-is. Please report this to the AutgoGraph team. When filing the bug, set the verbosity to 10 (on Linux, `export AUTOGRAPH_VERBOSITY=10`) and attach the full output. Cause: converting <bound method Pooling2D.call of <tensorflow.python.layers.pooling.MaxPooling2D object at 0x7f59b1e30f50>>: AssertionError: Bad argument number for Name: 3, expecting 4\n",
            "W0317 19:02:08.256870 140024544835456 ag_logging.py:145] Entity <bound method Pooling2D.call of <tensorflow.python.layers.pooling.MaxPooling2D object at 0x7f59b1e30f50>> could not be transformed and will be executed as-is. Please report this to the AutgoGraph team. When filing the bug, set the verbosity to 10 (on Linux, `export AUTOGRAPH_VERBOSITY=10`) and attach the full output. Cause: converting <bound method Pooling2D.call of <tensorflow.python.layers.pooling.MaxPooling2D object at 0x7f59b1e30f50>>: AssertionError: Bad argument number for Name: 3, expecting 4\n",
            "WARNING:tensorflow:Entity <bound method Conv.call of <tensorflow.python.layers.convolutional.Conv2D object at 0x7f59b1e3c210>> could not be transformed and will be executed as-is. Please report this to the AutgoGraph team. When filing the bug, set the verbosity to 10 (on Linux, `export AUTOGRAPH_VERBOSITY=10`) and attach the full output. Cause: converting <bound method Conv.call of <tensorflow.python.layers.convolutional.Conv2D object at 0x7f59b1e3c210>>: AssertionError: Bad argument number for Name: 3, expecting 4\n",
            "W0317 19:02:08.461695 140024544835456 ag_logging.py:145] Entity <bound method Conv.call of <tensorflow.python.layers.convolutional.Conv2D object at 0x7f59b1e3c210>> could not be transformed and will be executed as-is. Please report this to the AutgoGraph team. When filing the bug, set the verbosity to 10 (on Linux, `export AUTOGRAPH_VERBOSITY=10`) and attach the full output. Cause: converting <bound method Conv.call of <tensorflow.python.layers.convolutional.Conv2D object at 0x7f59b1e3c210>>: AssertionError: Bad argument number for Name: 3, expecting 4\n",
            "WARNING:tensorflow:Entity <bound method Conv.call of <tensorflow.python.layers.convolutional.Conv2D object at 0x7f59b1e3c7d0>> could not be transformed and will be executed as-is. Please report this to the AutgoGraph team. When filing the bug, set the verbosity to 10 (on Linux, `export AUTOGRAPH_VERBOSITY=10`) and attach the full output. Cause: converting <bound method Conv.call of <tensorflow.python.layers.convolutional.Conv2D object at 0x7f59b1e3c7d0>>: AssertionError: Bad argument number for Name: 3, expecting 4\n",
            "W0317 19:02:08.542932 140024544835456 ag_logging.py:145] Entity <bound method Conv.call of <tensorflow.python.layers.convolutional.Conv2D object at 0x7f59b1e3c7d0>> could not be transformed and will be executed as-is. Please report this to the AutgoGraph team. When filing the bug, set the verbosity to 10 (on Linux, `export AUTOGRAPH_VERBOSITY=10`) and attach the full output. Cause: converting <bound method Conv.call of <tensorflow.python.layers.convolutional.Conv2D object at 0x7f59b1e3c7d0>>: AssertionError: Bad argument number for Name: 3, expecting 4\n",
            "WARNING:tensorflow:Entity <bound method Pooling2D.call of <tensorflow.python.layers.pooling.MaxPooling2D object at 0x7f59b1e30a10>> could not be transformed and will be executed as-is. Please report this to the AutgoGraph team. When filing the bug, set the verbosity to 10 (on Linux, `export AUTOGRAPH_VERBOSITY=10`) and attach the full output. Cause: converting <bound method Pooling2D.call of <tensorflow.python.layers.pooling.MaxPooling2D object at 0x7f59b1e30a10>>: AssertionError: Bad argument number for Name: 3, expecting 4\n",
            "W0317 19:02:08.592193 140024544835456 ag_logging.py:145] Entity <bound method Pooling2D.call of <tensorflow.python.layers.pooling.MaxPooling2D object at 0x7f59b1e30a10>> could not be transformed and will be executed as-is. Please report this to the AutgoGraph team. When filing the bug, set the verbosity to 10 (on Linux, `export AUTOGRAPH_VERBOSITY=10`) and attach the full output. Cause: converting <bound method Pooling2D.call of <tensorflow.python.layers.pooling.MaxPooling2D object at 0x7f59b1e30a10>>: AssertionError: Bad argument number for Name: 3, expecting 4\n",
            "WARNING:tensorflow:Entity <bound method Conv.call of <tensorflow.python.layers.convolutional.Conv2D object at 0x7f59b1e3c790>> could not be transformed and will be executed as-is. Please report this to the AutgoGraph team. When filing the bug, set the verbosity to 10 (on Linux, `export AUTOGRAPH_VERBOSITY=10`) and attach the full output. Cause: converting <bound method Conv.call of <tensorflow.python.layers.convolutional.Conv2D object at 0x7f59b1e3c790>>: AssertionError: Bad argument number for Name: 3, expecting 4\n",
            "W0317 19:02:08.671759 140024544835456 ag_logging.py:145] Entity <bound method Conv.call of <tensorflow.python.layers.convolutional.Conv2D object at 0x7f59b1e3c790>> could not be transformed and will be executed as-is. Please report this to the AutgoGraph team. When filing the bug, set the verbosity to 10 (on Linux, `export AUTOGRAPH_VERBOSITY=10`) and attach the full output. Cause: converting <bound method Conv.call of <tensorflow.python.layers.convolutional.Conv2D object at 0x7f59b1e3c790>>: AssertionError: Bad argument number for Name: 3, expecting 4\n",
            "WARNING:tensorflow:Entity <bound method Conv.call of <tensorflow.python.layers.convolutional.Conv2D object at 0x7f59b1e3c1d0>> could not be transformed and will be executed as-is. Please report this to the AutgoGraph team. When filing the bug, set the verbosity to 10 (on Linux, `export AUTOGRAPH_VERBOSITY=10`) and attach the full output. Cause: converting <bound method Conv.call of <tensorflow.python.layers.convolutional.Conv2D object at 0x7f59b1e3c1d0>>: AssertionError: Bad argument number for Name: 3, expecting 4\n",
            "W0317 19:02:08.764888 140024544835456 ag_logging.py:145] Entity <bound method Conv.call of <tensorflow.python.layers.convolutional.Conv2D object at 0x7f59b1e3c1d0>> could not be transformed and will be executed as-is. Please report this to the AutgoGraph team. When filing the bug, set the verbosity to 10 (on Linux, `export AUTOGRAPH_VERBOSITY=10`) and attach the full output. Cause: converting <bound method Conv.call of <tensorflow.python.layers.convolutional.Conv2D object at 0x7f59b1e3c1d0>>: AssertionError: Bad argument number for Name: 3, expecting 4\n",
            "WARNING:tensorflow:Entity <bound method Conv.call of <tensorflow.python.layers.convolutional.Conv2D object at 0x7f59b1d35050>> could not be transformed and will be executed as-is. Please report this to the AutgoGraph team. When filing the bug, set the verbosity to 10 (on Linux, `export AUTOGRAPH_VERBOSITY=10`) and attach the full output. Cause: converting <bound method Conv.call of <tensorflow.python.layers.convolutional.Conv2D object at 0x7f59b1d35050>>: AssertionError: Bad argument number for Name: 3, expecting 4\n",
            "W0317 19:02:08.847316 140024544835456 ag_logging.py:145] Entity <bound method Conv.call of <tensorflow.python.layers.convolutional.Conv2D object at 0x7f59b1d35050>> could not be transformed and will be executed as-is. Please report this to the AutgoGraph team. When filing the bug, set the verbosity to 10 (on Linux, `export AUTOGRAPH_VERBOSITY=10`) and attach the full output. Cause: converting <bound method Conv.call of <tensorflow.python.layers.convolutional.Conv2D object at 0x7f59b1d35050>>: AssertionError: Bad argument number for Name: 3, expecting 4\n",
            "WARNING:tensorflow:Entity <bound method Pooling2D.call of <tensorflow.python.layers.pooling.MaxPooling2D object at 0x7f59b1e52150>> could not be transformed and will be executed as-is. Please report this to the AutgoGraph team. When filing the bug, set the verbosity to 10 (on Linux, `export AUTOGRAPH_VERBOSITY=10`) and attach the full output. Cause: converting <bound method Pooling2D.call of <tensorflow.python.layers.pooling.MaxPooling2D object at 0x7f59b1e52150>>: AssertionError: Bad argument number for Name: 3, expecting 4\n",
            "W0317 19:02:08.897007 140024544835456 ag_logging.py:145] Entity <bound method Pooling2D.call of <tensorflow.python.layers.pooling.MaxPooling2D object at 0x7f59b1e52150>> could not be transformed and will be executed as-is. Please report this to the AutgoGraph team. When filing the bug, set the verbosity to 10 (on Linux, `export AUTOGRAPH_VERBOSITY=10`) and attach the full output. Cause: converting <bound method Pooling2D.call of <tensorflow.python.layers.pooling.MaxPooling2D object at 0x7f59b1e52150>>: AssertionError: Bad argument number for Name: 3, expecting 4\n",
            "WARNING:tensorflow:Entity <bound method Conv.call of <tensorflow.python.layers.convolutional.Conv2D object at 0x7f59b1dde310>> could not be transformed and will be executed as-is. Please report this to the AutgoGraph team. When filing the bug, set the verbosity to 10 (on Linux, `export AUTOGRAPH_VERBOSITY=10`) and attach the full output. Cause: converting <bound method Conv.call of <tensorflow.python.layers.convolutional.Conv2D object at 0x7f59b1dde310>>: AssertionError: Bad argument number for Name: 3, expecting 4\n",
            "W0317 19:02:08.976150 140024544835456 ag_logging.py:145] Entity <bound method Conv.call of <tensorflow.python.layers.convolutional.Conv2D object at 0x7f59b1dde310>> could not be transformed and will be executed as-is. Please report this to the AutgoGraph team. When filing the bug, set the verbosity to 10 (on Linux, `export AUTOGRAPH_VERBOSITY=10`) and attach the full output. Cause: converting <bound method Conv.call of <tensorflow.python.layers.convolutional.Conv2D object at 0x7f59b1dde310>>: AssertionError: Bad argument number for Name: 3, expecting 4\n",
            "WARNING:tensorflow:Entity <bound method Conv.call of <tensorflow.python.layers.convolutional.Conv2D object at 0x7f59b28ddfd0>> could not be transformed and will be executed as-is. Please report this to the AutgoGraph team. When filing the bug, set the verbosity to 10 (on Linux, `export AUTOGRAPH_VERBOSITY=10`) and attach the full output. Cause: converting <bound method Conv.call of <tensorflow.python.layers.convolutional.Conv2D object at 0x7f59b28ddfd0>>: AssertionError: Bad argument number for Name: 3, expecting 4\n",
            "W0317 19:02:09.059172 140024544835456 ag_logging.py:145] Entity <bound method Conv.call of <tensorflow.python.layers.convolutional.Conv2D object at 0x7f59b28ddfd0>> could not be transformed and will be executed as-is. Please report this to the AutgoGraph team. When filing the bug, set the verbosity to 10 (on Linux, `export AUTOGRAPH_VERBOSITY=10`) and attach the full output. Cause: converting <bound method Conv.call of <tensorflow.python.layers.convolutional.Conv2D object at 0x7f59b28ddfd0>>: AssertionError: Bad argument number for Name: 3, expecting 4\n",
            "WARNING:tensorflow:Entity <bound method Conv.call of <tensorflow.python.layers.convolutional.Conv2D object at 0x7f59b1e307d0>> could not be transformed and will be executed as-is. Please report this to the AutgoGraph team. When filing the bug, set the verbosity to 10 (on Linux, `export AUTOGRAPH_VERBOSITY=10`) and attach the full output. Cause: converting <bound method Conv.call of <tensorflow.python.layers.convolutional.Conv2D object at 0x7f59b1e307d0>>: AssertionError: Bad argument number for Name: 3, expecting 4\n",
            "W0317 19:02:09.141578 140024544835456 ag_logging.py:145] Entity <bound method Conv.call of <tensorflow.python.layers.convolutional.Conv2D object at 0x7f59b1e307d0>> could not be transformed and will be executed as-is. Please report this to the AutgoGraph team. When filing the bug, set the verbosity to 10 (on Linux, `export AUTOGRAPH_VERBOSITY=10`) and attach the full output. Cause: converting <bound method Conv.call of <tensorflow.python.layers.convolutional.Conv2D object at 0x7f59b1e307d0>>: AssertionError: Bad argument number for Name: 3, expecting 4\n",
            "WARNING:tensorflow:Entity <bound method Pooling2D.call of <tensorflow.python.layers.pooling.MaxPooling2D object at 0x7f59b28bff10>> could not be transformed and will be executed as-is. Please report this to the AutgoGraph team. When filing the bug, set the verbosity to 10 (on Linux, `export AUTOGRAPH_VERBOSITY=10`) and attach the full output. Cause: converting <bound method Pooling2D.call of <tensorflow.python.layers.pooling.MaxPooling2D object at 0x7f59b28bff10>>: AssertionError: Bad argument number for Name: 3, expecting 4\n",
            "W0317 19:02:09.195718 140024544835456 ag_logging.py:145] Entity <bound method Pooling2D.call of <tensorflow.python.layers.pooling.MaxPooling2D object at 0x7f59b28bff10>> could not be transformed and will be executed as-is. Please report this to the AutgoGraph team. When filing the bug, set the verbosity to 10 (on Linux, `export AUTOGRAPH_VERBOSITY=10`) and attach the full output. Cause: converting <bound method Pooling2D.call of <tensorflow.python.layers.pooling.MaxPooling2D object at 0x7f59b28bff10>>: AssertionError: Bad argument number for Name: 3, expecting 4\n",
            "WARNING:tensorflow:Entity <bound method Conv.call of <tensorflow.python.layers.convolutional.Conv2D object at 0x7f59b1e02410>> could not be transformed and will be executed as-is. Please report this to the AutgoGraph team. When filing the bug, set the verbosity to 10 (on Linux, `export AUTOGRAPH_VERBOSITY=10`) and attach the full output. Cause: converting <bound method Conv.call of <tensorflow.python.layers.convolutional.Conv2D object at 0x7f59b1e02410>>: AssertionError: Bad argument number for Name: 3, expecting 4\n",
            "W0317 19:02:09.275738 140024544835456 ag_logging.py:145] Entity <bound method Conv.call of <tensorflow.python.layers.convolutional.Conv2D object at 0x7f59b1e02410>> could not be transformed and will be executed as-is. Please report this to the AutgoGraph team. When filing the bug, set the verbosity to 10 (on Linux, `export AUTOGRAPH_VERBOSITY=10`) and attach the full output. Cause: converting <bound method Conv.call of <tensorflow.python.layers.convolutional.Conv2D object at 0x7f59b1e02410>>: AssertionError: Bad argument number for Name: 3, expecting 4\n",
            "WARNING:tensorflow:Entity <bound method Conv.call of <tensorflow.python.layers.convolutional.Conv2D object at 0x7f59b1d53f50>> could not be transformed and will be executed as-is. Please report this to the AutgoGraph team. When filing the bug, set the verbosity to 10 (on Linux, `export AUTOGRAPH_VERBOSITY=10`) and attach the full output. Cause: converting <bound method Conv.call of <tensorflow.python.layers.convolutional.Conv2D object at 0x7f59b1d53f50>>: AssertionError: Bad argument number for Name: 3, expecting 4\n",
            "W0317 19:02:09.360225 140024544835456 ag_logging.py:145] Entity <bound method Conv.call of <tensorflow.python.layers.convolutional.Conv2D object at 0x7f59b1d53f50>> could not be transformed and will be executed as-is. Please report this to the AutgoGraph team. When filing the bug, set the verbosity to 10 (on Linux, `export AUTOGRAPH_VERBOSITY=10`) and attach the full output. Cause: converting <bound method Conv.call of <tensorflow.python.layers.convolutional.Conv2D object at 0x7f59b1d53f50>>: AssertionError: Bad argument number for Name: 3, expecting 4\n",
            "WARNING:tensorflow:Entity <bound method Conv.call of <tensorflow.python.layers.convolutional.Conv2D object at 0x7f59b1ddef50>> could not be transformed and will be executed as-is. Please report this to the AutgoGraph team. When filing the bug, set the verbosity to 10 (on Linux, `export AUTOGRAPH_VERBOSITY=10`) and attach the full output. Cause: converting <bound method Conv.call of <tensorflow.python.layers.convolutional.Conv2D object at 0x7f59b1ddef50>>: AssertionError: Bad argument number for Name: 3, expecting 4\n",
            "W0317 19:02:09.442919 140024544835456 ag_logging.py:145] Entity <bound method Conv.call of <tensorflow.python.layers.convolutional.Conv2D object at 0x7f59b1ddef50>> could not be transformed and will be executed as-is. Please report this to the AutgoGraph team. When filing the bug, set the verbosity to 10 (on Linux, `export AUTOGRAPH_VERBOSITY=10`) and attach the full output. Cause: converting <bound method Conv.call of <tensorflow.python.layers.convolutional.Conv2D object at 0x7f59b1ddef50>>: AssertionError: Bad argument number for Name: 3, expecting 4\n",
            "WARNING:tensorflow:Entity <bound method Conv.call of <tensorflow.python.layers.convolutional.Conv2D object at 0x7f59b28ddfd0>> could not be transformed and will be executed as-is. Please report this to the AutgoGraph team. When filing the bug, set the verbosity to 10 (on Linux, `export AUTOGRAPH_VERBOSITY=10`) and attach the full output. Cause: converting <bound method Conv.call of <tensorflow.python.layers.convolutional.Conv2D object at 0x7f59b28ddfd0>>: AssertionError: Bad argument number for Name: 3, expecting 4\n",
            "W0317 19:02:09.522345 140024544835456 ag_logging.py:145] Entity <bound method Conv.call of <tensorflow.python.layers.convolutional.Conv2D object at 0x7f59b28ddfd0>> could not be transformed and will be executed as-is. Please report this to the AutgoGraph team. When filing the bug, set the verbosity to 10 (on Linux, `export AUTOGRAPH_VERBOSITY=10`) and attach the full output. Cause: converting <bound method Conv.call of <tensorflow.python.layers.convolutional.Conv2D object at 0x7f59b28ddfd0>>: AssertionError: Bad argument number for Name: 3, expecting 4\n",
            "WARNING:tensorflow:From /content/text-detection-ctpn/nets/model_train.py:30: LSTMCell.__init__ (from tensorflow.python.ops.rnn_cell_impl) is deprecated and will be removed in a future version.\n",
            "Instructions for updating:\n",
            "This class is equivalent as tf.keras.layers.LSTMCell, and will be replaced by that in Tensorflow 2.0.\n",
            "W0317 19:02:09.538686 140024544835456 deprecation.py:323] From /content/text-detection-ctpn/nets/model_train.py:30: LSTMCell.__init__ (from tensorflow.python.ops.rnn_cell_impl) is deprecated and will be removed in a future version.\n",
            "Instructions for updating:\n",
            "This class is equivalent as tf.keras.layers.LSTMCell, and will be replaced by that in Tensorflow 2.0.\n",
            "WARNING:tensorflow:From /content/text-detection-ctpn/nets/model_train.py:33: bidirectional_dynamic_rnn (from tensorflow.python.ops.rnn) is deprecated and will be removed in a future version.\n",
            "Instructions for updating:\n",
            "Please use `keras.layers.Bidirectional(keras.layers.RNN(cell))`, which is equivalent to this API\n",
            "W0317 19:02:09.539499 140024544835456 deprecation.py:323] From /content/text-detection-ctpn/nets/model_train.py:33: bidirectional_dynamic_rnn (from tensorflow.python.ops.rnn) is deprecated and will be removed in a future version.\n",
            "Instructions for updating:\n",
            "Please use `keras.layers.Bidirectional(keras.layers.RNN(cell))`, which is equivalent to this API\n",
            "WARNING:tensorflow:From /usr/local/lib/python3.7/dist-packages/tensorflow/python/ops/rnn.py:464: dynamic_rnn (from tensorflow.python.ops.rnn) is deprecated and will be removed in a future version.\n",
            "Instructions for updating:\n",
            "Please use `keras.layers.RNN(cell)`, which is equivalent to this API\n",
            "W0317 19:02:09.539918 140024544835456 deprecation.py:323] From /usr/local/lib/python3.7/dist-packages/tensorflow/python/ops/rnn.py:464: dynamic_rnn (from tensorflow.python.ops.rnn) is deprecated and will be removed in a future version.\n",
            "Instructions for updating:\n",
            "Please use `keras.layers.RNN(cell)`, which is equivalent to this API\n",
            "WARNING:tensorflow:From /usr/local/lib/python3.7/dist-packages/tensorflow/python/ops/init_ops.py:1251: calling VarianceScaling.__init__ (from tensorflow.python.ops.init_ops) with dtype is deprecated and will be removed in a future version.\n",
            "Instructions for updating:\n",
            "Call initializer instance with the dtype argument instead of passing it to the constructor\n",
            "W0317 19:02:09.606067 140024544835456 deprecation.py:506] From /usr/local/lib/python3.7/dist-packages/tensorflow/python/ops/init_ops.py:1251: calling VarianceScaling.__init__ (from tensorflow.python.ops.init_ops) with dtype is deprecated and will be removed in a future version.\n",
            "Instructions for updating:\n",
            "Call initializer instance with the dtype argument instead of passing it to the constructor\n",
            "WARNING:tensorflow:From /usr/local/lib/python3.7/dist-packages/tensorflow/python/ops/rnn_cell_impl.py:961: calling Zeros.__init__ (from tensorflow.python.ops.init_ops) with dtype is deprecated and will be removed in a future version.\n",
            "Instructions for updating:\n",
            "Call initializer instance with the dtype argument instead of passing it to the constructor\n",
            "W0317 19:02:09.618978 140024544835456 deprecation.py:506] From /usr/local/lib/python3.7/dist-packages/tensorflow/python/ops/rnn_cell_impl.py:961: calling Zeros.__init__ (from tensorflow.python.ops.init_ops) with dtype is deprecated and will be removed in a future version.\n",
            "Instructions for updating:\n",
            "Call initializer instance with the dtype argument instead of passing it to the constructor\n",
            "WARNING:tensorflow:Entity <bound method LSTMCell.call of <tensorflow.python.ops.rnn_cell_impl.LSTMCell object at 0x7f59b5c62050>> could not be transformed and will be executed as-is. Please report this to the AutgoGraph team. When filing the bug, set the verbosity to 10 (on Linux, `export AUTOGRAPH_VERBOSITY=10`) and attach the full output. Cause: converting <bound method LSTMCell.call of <tensorflow.python.ops.rnn_cell_impl.LSTMCell object at 0x7f59b5c62050>>: AttributeError: module 'gast' has no attribute 'Num'\n",
            "W0317 19:02:09.645792 140024544835456 ag_logging.py:145] Entity <bound method LSTMCell.call of <tensorflow.python.ops.rnn_cell_impl.LSTMCell object at 0x7f59b5c62050>> could not be transformed and will be executed as-is. Please report this to the AutgoGraph team. When filing the bug, set the verbosity to 10 (on Linux, `export AUTOGRAPH_VERBOSITY=10`) and attach the full output. Cause: converting <bound method LSTMCell.call of <tensorflow.python.ops.rnn_cell_impl.LSTMCell object at 0x7f59b5c62050>>: AttributeError: module 'gast' has no attribute 'Num'\n",
            "WARNING:tensorflow:Entity <bound method LSTMCell.call of <tensorflow.python.ops.rnn_cell_impl.LSTMCell object at 0x7f59b1c8e3d0>> could not be transformed and will be executed as-is. Please report this to the AutgoGraph team. When filing the bug, set the verbosity to 10 (on Linux, `export AUTOGRAPH_VERBOSITY=10`) and attach the full output. Cause: converting <bound method LSTMCell.call of <tensorflow.python.ops.rnn_cell_impl.LSTMCell object at 0x7f59b1c8e3d0>>: AttributeError: module 'gast' has no attribute 'Num'\n",
            "W0317 19:02:09.790903 140024544835456 ag_logging.py:145] Entity <bound method LSTMCell.call of <tensorflow.python.ops.rnn_cell_impl.LSTMCell object at 0x7f59b1c8e3d0>> could not be transformed and will be executed as-is. Please report this to the AutgoGraph team. When filing the bug, set the verbosity to 10 (on Linux, `export AUTOGRAPH_VERBOSITY=10`) and attach the full output. Cause: converting <bound method LSTMCell.call of <tensorflow.python.ops.rnn_cell_impl.LSTMCell object at 0x7f59b1c8e3d0>>: AttributeError: module 'gast' has no attribute 'Num'\n",
            "WARNING:tensorflow:From /content/text-detection-ctpn/nets/model_train.py:95: py_func (from tensorflow.python.ops.script_ops) is deprecated and will be removed in a future version.\n",
            "Instructions for updating:\n",
            "tf.py_func is deprecated in TF V2. Instead, there are two\n",
            "    options available in V2.\n",
            "    - tf.py_function takes a python function which manipulates tf eager\n",
            "    tensors instead of numpy arrays. It's easy to convert a tf eager tensor to\n",
            "    an ndarray (just call tensor.numpy()) but having access to eager tensors\n",
            "    means `tf.py_function`s can use accelerators such as GPUs as well as\n",
            "    being differentiable using a gradient tape.\n",
            "    - tf.numpy_function maintains the semantics of the deprecated tf.py_func\n",
            "    (it is not differentiable, and manipulates numpy arrays). It drops the\n",
            "    stateful argument making all functions stateful.\n",
            "    \n",
            "W0317 19:02:09.926008 140024544835456 deprecation.py:323] From /content/text-detection-ctpn/nets/model_train.py:95: py_func (from tensorflow.python.ops.script_ops) is deprecated and will be removed in a future version.\n",
            "Instructions for updating:\n",
            "tf.py_func is deprecated in TF V2. Instead, there are two\n",
            "    options available in V2.\n",
            "    - tf.py_function takes a python function which manipulates tf eager\n",
            "    tensors instead of numpy arrays. It's easy to convert a tf eager tensor to\n",
            "    an ndarray (just call tensor.numpy()) but having access to eager tensors\n",
            "    means `tf.py_function`s can use accelerators such as GPUs as well as\n",
            "    being differentiable using a gradient tape.\n",
            "    - tf.numpy_function maintains the semantics of the deprecated tf.py_func\n",
            "    (it is not differentiable, and manipulates numpy arrays). It drops the\n",
            "    stateful argument making all functions stateful.\n",
            "    \n",
            "WARNING:tensorflow:From /content/text-detection-ctpn/nets/model_train.py:128: add_dispatch_support.<locals>.wrapper (from tensorflow.python.ops.array_ops) is deprecated and will be removed in a future version.\n",
            "Instructions for updating:\n",
            "Use tf.where in 2.0, which has the same broadcast rule as np.where\n",
            "W0317 19:02:09.941674 140024544835456 deprecation.py:323] From /content/text-detection-ctpn/nets/model_train.py:128: add_dispatch_support.<locals>.wrapper (from tensorflow.python.ops.array_ops) is deprecated and will be removed in a future version.\n",
            "Instructions for updating:\n",
            "Use tf.where in 2.0, which has the same broadcast rule as np.where\n",
            "WARNING:tensorflow:From /content/text-detection-ctpn/nets/model_train.py:152: The name tf.get_collection is deprecated. Please use tf.compat.v1.get_collection instead.\n",
            "\n",
            "W0317 19:02:09.994593 140024544835456 deprecation_wrapper.py:119] From /content/text-detection-ctpn/nets/model_train.py:152: The name tf.get_collection is deprecated. Please use tf.compat.v1.get_collection instead.\n",
            "\n",
            "WARNING:tensorflow:From /content/text-detection-ctpn/nets/model_train.py:152: The name tf.GraphKeys is deprecated. Please use tf.compat.v1.GraphKeys instead.\n",
            "\n",
            "W0317 19:02:09.994910 140024544835456 deprecation_wrapper.py:119] From /content/text-detection-ctpn/nets/model_train.py:152: The name tf.GraphKeys is deprecated. Please use tf.compat.v1.GraphKeys instead.\n",
            "\n",
            "WARNING:tensorflow:From ./main/train.py:56: The name tf.summary.merge_all is deprecated. Please use tf.compat.v1.summary.merge_all instead.\n",
            "\n",
            "W0317 19:02:11.479511 140024544835456 deprecation_wrapper.py:119] From ./main/train.py:56: The name tf.summary.merge_all is deprecated. Please use tf.compat.v1.summary.merge_all instead.\n",
            "\n",
            "WARNING:tensorflow:From /usr/local/lib/python3.7/dist-packages/tensorflow/python/training/moving_averages.py:433: Variable.initialized_value (from tensorflow.python.ops.variables) is deprecated and will be removed in a future version.\n",
            "Instructions for updating:\n",
            "Use Variable.read_value. Variables in 2.X are initialized automatically both in eager and graph (inside tf.defun) contexts.\n",
            "W0317 19:02:11.480740 140024544835456 deprecation.py:323] From /usr/local/lib/python3.7/dist-packages/tensorflow/python/training/moving_averages.py:433: Variable.initialized_value (from tensorflow.python.ops.variables) is deprecated and will be removed in a future version.\n",
            "Instructions for updating:\n",
            "Use Variable.read_value. Variables in 2.X are initialized automatically both in eager and graph (inside tf.defun) contexts.\n",
            "WARNING:tensorflow:From ./main/train.py:63: The name tf.train.Saver is deprecated. Please use tf.compat.v1.train.Saver instead.\n",
            "\n",
            "W0317 19:02:12.330378 140024544835456 deprecation_wrapper.py:119] From ./main/train.py:63: The name tf.train.Saver is deprecated. Please use tf.compat.v1.train.Saver instead.\n",
            "\n",
            "WARNING:tensorflow:From ./main/train.py:64: The name tf.summary.FileWriter is deprecated. Please use tf.compat.v1.summary.FileWriter instead.\n",
            "\n",
            "W0317 19:02:12.620609 140024544835456 deprecation_wrapper.py:119] From ./main/train.py:64: The name tf.summary.FileWriter is deprecated. Please use tf.compat.v1.summary.FileWriter instead.\n",
            "\n",
            "2021-03-17 19:02:13.078065: W tensorflow/core/util/tensor_slice_reader.cc:95] Could not open data/vgg_16.ckpt: Data loss: not an sstable (bad magic number): perhaps your file is in a different file format and you need to use a different restore operator?\n",
            "Traceback (most recent call last):\n",
            "  File \"./main/train.py\", line 117, in <module>\n",
            "    tf.app.run()\n",
            "  File \"/usr/local/lib/python3.7/dist-packages/tensorflow/python/platform/app.py\", line 40, in run\n",
            "    _run(main=main, argv=argv, flags_parser=_parse_flags_tolerate_undef)\n",
            "  File \"/usr/local/lib/python3.7/dist-packages/absl/app.py\", line 300, in run\n",
            "    _run_main(main, args)\n",
            "  File \"/usr/local/lib/python3.7/dist-packages/absl/app.py\", line 251, in _run_main\n",
            "    sys.exit(main(argv))\n",
            "  File \"./main/train.py\", line 71, in main\n",
            "    ignore_missing_vars=True)\n",
            "  File \"/usr/local/lib/python3.7/dist-packages/tensorflow/contrib/framework/python/ops/variables.py\", line 746, in assign_from_checkpoint_fn\n",
            "    reader = pywrap_tensorflow.NewCheckpointReader(model_path)\n",
            "  File \"/usr/local/lib/python3.7/dist-packages/tensorflow/python/pywrap_tensorflow_internal.py\", line 636, in NewCheckpointReader\n",
            "    return CheckpointReader(compat.as_bytes(filepattern))\n",
            "  File \"/usr/local/lib/python3.7/dist-packages/tensorflow/python/pywrap_tensorflow_internal.py\", line 648, in __init__\n",
            "    this = _pywrap_tensorflow_internal.new_CheckpointReader(filename)\n",
            "tensorflow.python.framework.errors_impl.DataLossError: Unable to open table file data/vgg_16.ckpt: Data loss: not an sstable (bad magic number): perhaps your file is in a different file format and you need to use a different restore operator?\n"
          ],
          "name": "stdout"
        }
      ]
    },
    {
      "cell_type": "code",
      "metadata": {
        "colab": {
          "base_uri": "https://localhost:8080/"
        },
        "id": "3A32E_umiybs",
        "outputId": "19abfacd-5ea2-4c2b-cf7f-8e442c975086"
      },
      "source": [
        "!python ./main/demo.py"
      ],
      "execution_count": 56,
      "outputs": [
        {
          "output_type": "stream",
          "text": [
            "/usr/local/lib/python3.7/dist-packages/tensorflow/python/framework/dtypes.py:516: FutureWarning: Passing (type, 1) or '1type' as a synonym of type is deprecated; in a future version of numpy, it will be understood as (type, (1,)) / '(1,)type'.\n",
            "  _np_qint8 = np.dtype([(\"qint8\", np.int8, 1)])\n",
            "/usr/local/lib/python3.7/dist-packages/tensorflow/python/framework/dtypes.py:517: FutureWarning: Passing (type, 1) or '1type' as a synonym of type is deprecated; in a future version of numpy, it will be understood as (type, (1,)) / '(1,)type'.\n",
            "  _np_quint8 = np.dtype([(\"quint8\", np.uint8, 1)])\n",
            "/usr/local/lib/python3.7/dist-packages/tensorflow/python/framework/dtypes.py:518: FutureWarning: Passing (type, 1) or '1type' as a synonym of type is deprecated; in a future version of numpy, it will be understood as (type, (1,)) / '(1,)type'.\n",
            "  _np_qint16 = np.dtype([(\"qint16\", np.int16, 1)])\n",
            "/usr/local/lib/python3.7/dist-packages/tensorflow/python/framework/dtypes.py:519: FutureWarning: Passing (type, 1) or '1type' as a synonym of type is deprecated; in a future version of numpy, it will be understood as (type, (1,)) / '(1,)type'.\n",
            "  _np_quint16 = np.dtype([(\"quint16\", np.uint16, 1)])\n",
            "/usr/local/lib/python3.7/dist-packages/tensorflow/python/framework/dtypes.py:520: FutureWarning: Passing (type, 1) or '1type' as a synonym of type is deprecated; in a future version of numpy, it will be understood as (type, (1,)) / '(1,)type'.\n",
            "  _np_qint32 = np.dtype([(\"qint32\", np.int32, 1)])\n",
            "/usr/local/lib/python3.7/dist-packages/tensorflow/python/framework/dtypes.py:525: FutureWarning: Passing (type, 1) or '1type' as a synonym of type is deprecated; in a future version of numpy, it will be understood as (type, (1,)) / '(1,)type'.\n",
            "  np_resource = np.dtype([(\"resource\", np.ubyte, 1)])\n",
            "/usr/local/lib/python3.7/dist-packages/tensorboard/compat/tensorflow_stub/dtypes.py:541: FutureWarning: Passing (type, 1) or '1type' as a synonym of type is deprecated; in a future version of numpy, it will be understood as (type, (1,)) / '(1,)type'.\n",
            "  _np_qint8 = np.dtype([(\"qint8\", np.int8, 1)])\n",
            "/usr/local/lib/python3.7/dist-packages/tensorboard/compat/tensorflow_stub/dtypes.py:542: FutureWarning: Passing (type, 1) or '1type' as a synonym of type is deprecated; in a future version of numpy, it will be understood as (type, (1,)) / '(1,)type'.\n",
            "  _np_quint8 = np.dtype([(\"quint8\", np.uint8, 1)])\n",
            "/usr/local/lib/python3.7/dist-packages/tensorboard/compat/tensorflow_stub/dtypes.py:543: FutureWarning: Passing (type, 1) or '1type' as a synonym of type is deprecated; in a future version of numpy, it will be understood as (type, (1,)) / '(1,)type'.\n",
            "  _np_qint16 = np.dtype([(\"qint16\", np.int16, 1)])\n",
            "/usr/local/lib/python3.7/dist-packages/tensorboard/compat/tensorflow_stub/dtypes.py:544: FutureWarning: Passing (type, 1) or '1type' as a synonym of type is deprecated; in a future version of numpy, it will be understood as (type, (1,)) / '(1,)type'.\n",
            "  _np_quint16 = np.dtype([(\"quint16\", np.uint16, 1)])\n",
            "/usr/local/lib/python3.7/dist-packages/tensorboard/compat/tensorflow_stub/dtypes.py:545: FutureWarning: Passing (type, 1) or '1type' as a synonym of type is deprecated; in a future version of numpy, it will be understood as (type, (1,)) / '(1,)type'.\n",
            "  _np_qint32 = np.dtype([(\"qint32\", np.int32, 1)])\n",
            "/usr/local/lib/python3.7/dist-packages/tensorboard/compat/tensorflow_stub/dtypes.py:550: FutureWarning: Passing (type, 1) or '1type' as a synonym of type is deprecated; in a future version of numpy, it will be understood as (type, (1,)) / '(1,)type'.\n",
            "  np_resource = np.dtype([(\"resource\", np.ubyte, 1)])\n",
            "WARNING:tensorflow:From ./main/demo.py:121: The name tf.app.run is deprecated. Please use tf.compat.v1.app.run instead.\n",
            "\n",
            "WARNING:tensorflow:From ./main/demo.py:60: The name tf.get_default_graph is deprecated. Please use tf.compat.v1.get_default_graph instead.\n",
            "\n",
            "W0317 18:54:10.129077 140450983094144 deprecation_wrapper.py:119] From ./main/demo.py:60: The name tf.get_default_graph is deprecated. Please use tf.compat.v1.get_default_graph instead.\n",
            "\n",
            "WARNING:tensorflow:From ./main/demo.py:61: The name tf.placeholder is deprecated. Please use tf.compat.v1.placeholder instead.\n",
            "\n",
            "W0317 18:54:10.129865 140450983094144 deprecation_wrapper.py:119] From ./main/demo.py:61: The name tf.placeholder is deprecated. Please use tf.compat.v1.placeholder instead.\n",
            "\n",
            "WARNING:tensorflow:From ./main/demo.py:64: The name tf.get_variable is deprecated. Please use tf.compat.v1.get_variable instead.\n",
            "\n",
            "W0317 18:54:10.133547 140450983094144 deprecation_wrapper.py:119] From ./main/demo.py:64: The name tf.get_variable is deprecated. Please use tf.compat.v1.get_variable instead.\n",
            "\n",
            "WARNING:tensorflow:From /content/text-detection-ctpn/nets/vgg.py:16: The name tf.variable_scope is deprecated. Please use tf.compat.v1.variable_scope instead.\n",
            "\n",
            "W0317 18:54:10.148434 140450983094144 deprecation_wrapper.py:119] From /content/text-detection-ctpn/nets/vgg.py:16: The name tf.variable_scope is deprecated. Please use tf.compat.v1.variable_scope instead.\n",
            "\n",
            "WARNING:tensorflow:Entity <bound method Conv.call of <tensorflow.python.layers.convolutional.Conv2D object at 0x7fbd004f7490>> could not be transformed and will be executed as-is. Please report this to the AutgoGraph team. When filing the bug, set the verbosity to 10 (on Linux, `export AUTOGRAPH_VERBOSITY=10`) and attach the full output. Cause: converting <bound method Conv.call of <tensorflow.python.layers.convolutional.Conv2D object at 0x7fbd004f7490>>: AssertionError: Bad argument number for Name: 3, expecting 4\n",
            "W0317 18:54:10.237687 140450983094144 ag_logging.py:145] Entity <bound method Conv.call of <tensorflow.python.layers.convolutional.Conv2D object at 0x7fbd004f7490>> could not be transformed and will be executed as-is. Please report this to the AutgoGraph team. When filing the bug, set the verbosity to 10 (on Linux, `export AUTOGRAPH_VERBOSITY=10`) and attach the full output. Cause: converting <bound method Conv.call of <tensorflow.python.layers.convolutional.Conv2D object at 0x7fbd004f7490>>: AssertionError: Bad argument number for Name: 3, expecting 4\n",
            "WARNING:tensorflow:Entity <bound method Conv.call of <tensorflow.python.layers.convolutional.Conv2D object at 0x7fbd004f7590>> could not be transformed and will be executed as-is. Please report this to the AutgoGraph team. When filing the bug, set the verbosity to 10 (on Linux, `export AUTOGRAPH_VERBOSITY=10`) and attach the full output. Cause: converting <bound method Conv.call of <tensorflow.python.layers.convolutional.Conv2D object at 0x7fbd004f7590>>: AssertionError: Bad argument number for Name: 3, expecting 4\n",
            "W0317 18:54:10.319280 140450983094144 ag_logging.py:145] Entity <bound method Conv.call of <tensorflow.python.layers.convolutional.Conv2D object at 0x7fbd004f7590>> could not be transformed and will be executed as-is. Please report this to the AutgoGraph team. When filing the bug, set the verbosity to 10 (on Linux, `export AUTOGRAPH_VERBOSITY=10`) and attach the full output. Cause: converting <bound method Conv.call of <tensorflow.python.layers.convolutional.Conv2D object at 0x7fbd004f7590>>: AssertionError: Bad argument number for Name: 3, expecting 4\n",
            "WARNING:tensorflow:Entity <bound method Pooling2D.call of <tensorflow.python.layers.pooling.MaxPooling2D object at 0x7fbd00562e90>> could not be transformed and will be executed as-is. Please report this to the AutgoGraph team. When filing the bug, set the verbosity to 10 (on Linux, `export AUTOGRAPH_VERBOSITY=10`) and attach the full output. Cause: converting <bound method Pooling2D.call of <tensorflow.python.layers.pooling.MaxPooling2D object at 0x7fbd00562e90>>: AssertionError: Bad argument number for Name: 3, expecting 4\n",
            "W0317 18:54:10.368772 140450983094144 ag_logging.py:145] Entity <bound method Pooling2D.call of <tensorflow.python.layers.pooling.MaxPooling2D object at 0x7fbd00562e90>> could not be transformed and will be executed as-is. Please report this to the AutgoGraph team. When filing the bug, set the verbosity to 10 (on Linux, `export AUTOGRAPH_VERBOSITY=10`) and attach the full output. Cause: converting <bound method Pooling2D.call of <tensorflow.python.layers.pooling.MaxPooling2D object at 0x7fbd00562e90>>: AssertionError: Bad argument number for Name: 3, expecting 4\n",
            "WARNING:tensorflow:Entity <bound method Conv.call of <tensorflow.python.layers.convolutional.Conv2D object at 0x7fbd004f7750>> could not be transformed and will be executed as-is. Please report this to the AutgoGraph team. When filing the bug, set the verbosity to 10 (on Linux, `export AUTOGRAPH_VERBOSITY=10`) and attach the full output. Cause: converting <bound method Conv.call of <tensorflow.python.layers.convolutional.Conv2D object at 0x7fbd004f7750>>: AssertionError: Bad argument number for Name: 3, expecting 4\n",
            "W0317 18:54:10.455384 140450983094144 ag_logging.py:145] Entity <bound method Conv.call of <tensorflow.python.layers.convolutional.Conv2D object at 0x7fbd004f7750>> could not be transformed and will be executed as-is. Please report this to the AutgoGraph team. When filing the bug, set the verbosity to 10 (on Linux, `export AUTOGRAPH_VERBOSITY=10`) and attach the full output. Cause: converting <bound method Conv.call of <tensorflow.python.layers.convolutional.Conv2D object at 0x7fbd004f7750>>: AssertionError: Bad argument number for Name: 3, expecting 4\n",
            "WARNING:tensorflow:Entity <bound method Conv.call of <tensorflow.python.layers.convolutional.Conv2D object at 0x7fbd004f7210>> could not be transformed and will be executed as-is. Please report this to the AutgoGraph team. When filing the bug, set the verbosity to 10 (on Linux, `export AUTOGRAPH_VERBOSITY=10`) and attach the full output. Cause: converting <bound method Conv.call of <tensorflow.python.layers.convolutional.Conv2D object at 0x7fbd004f7210>>: AssertionError: Bad argument number for Name: 3, expecting 4\n",
            "W0317 18:54:10.536701 140450983094144 ag_logging.py:145] Entity <bound method Conv.call of <tensorflow.python.layers.convolutional.Conv2D object at 0x7fbd004f7210>> could not be transformed and will be executed as-is. Please report this to the AutgoGraph team. When filing the bug, set the verbosity to 10 (on Linux, `export AUTOGRAPH_VERBOSITY=10`) and attach the full output. Cause: converting <bound method Conv.call of <tensorflow.python.layers.convolutional.Conv2D object at 0x7fbd004f7210>>: AssertionError: Bad argument number for Name: 3, expecting 4\n",
            "WARNING:tensorflow:Entity <bound method Pooling2D.call of <tensorflow.python.layers.pooling.MaxPooling2D object at 0x7fbd00562910>> could not be transformed and will be executed as-is. Please report this to the AutgoGraph team. When filing the bug, set the verbosity to 10 (on Linux, `export AUTOGRAPH_VERBOSITY=10`) and attach the full output. Cause: converting <bound method Pooling2D.call of <tensorflow.python.layers.pooling.MaxPooling2D object at 0x7fbd00562910>>: AssertionError: Bad argument number for Name: 3, expecting 4\n",
            "W0317 18:54:10.585405 140450983094144 ag_logging.py:145] Entity <bound method Pooling2D.call of <tensorflow.python.layers.pooling.MaxPooling2D object at 0x7fbd00562910>> could not be transformed and will be executed as-is. Please report this to the AutgoGraph team. When filing the bug, set the verbosity to 10 (on Linux, `export AUTOGRAPH_VERBOSITY=10`) and attach the full output. Cause: converting <bound method Pooling2D.call of <tensorflow.python.layers.pooling.MaxPooling2D object at 0x7fbd00562910>>: AssertionError: Bad argument number for Name: 3, expecting 4\n",
            "WARNING:tensorflow:Entity <bound method Conv.call of <tensorflow.python.layers.convolutional.Conv2D object at 0x7fbd004f7150>> could not be transformed and will be executed as-is. Please report this to the AutgoGraph team. When filing the bug, set the verbosity to 10 (on Linux, `export AUTOGRAPH_VERBOSITY=10`) and attach the full output. Cause: converting <bound method Conv.call of <tensorflow.python.layers.convolutional.Conv2D object at 0x7fbd004f7150>>: AssertionError: Bad argument number for Name: 3, expecting 4\n",
            "W0317 18:54:10.665418 140450983094144 ag_logging.py:145] Entity <bound method Conv.call of <tensorflow.python.layers.convolutional.Conv2D object at 0x7fbd004f7150>> could not be transformed and will be executed as-is. Please report this to the AutgoGraph team. When filing the bug, set the verbosity to 10 (on Linux, `export AUTOGRAPH_VERBOSITY=10`) and attach the full output. Cause: converting <bound method Conv.call of <tensorflow.python.layers.convolutional.Conv2D object at 0x7fbd004f7150>>: AssertionError: Bad argument number for Name: 3, expecting 4\n",
            "WARNING:tensorflow:Entity <bound method Conv.call of <tensorflow.python.layers.convolutional.Conv2D object at 0x7fbd005114d0>> could not be transformed and will be executed as-is. Please report this to the AutgoGraph team. When filing the bug, set the verbosity to 10 (on Linux, `export AUTOGRAPH_VERBOSITY=10`) and attach the full output. Cause: converting <bound method Conv.call of <tensorflow.python.layers.convolutional.Conv2D object at 0x7fbd005114d0>>: AssertionError: Bad argument number for Name: 3, expecting 4\n",
            "W0317 18:54:10.751036 140450983094144 ag_logging.py:145] Entity <bound method Conv.call of <tensorflow.python.layers.convolutional.Conv2D object at 0x7fbd005114d0>> could not be transformed and will be executed as-is. Please report this to the AutgoGraph team. When filing the bug, set the verbosity to 10 (on Linux, `export AUTOGRAPH_VERBOSITY=10`) and attach the full output. Cause: converting <bound method Conv.call of <tensorflow.python.layers.convolutional.Conv2D object at 0x7fbd005114d0>>: AssertionError: Bad argument number for Name: 3, expecting 4\n",
            "WARNING:tensorflow:Entity <bound method Conv.call of <tensorflow.python.layers.convolutional.Conv2D object at 0x7fbd004f7050>> could not be transformed and will be executed as-is. Please report this to the AutgoGraph team. When filing the bug, set the verbosity to 10 (on Linux, `export AUTOGRAPH_VERBOSITY=10`) and attach the full output. Cause: converting <bound method Conv.call of <tensorflow.python.layers.convolutional.Conv2D object at 0x7fbd004f7050>>: AssertionError: Bad argument number for Name: 3, expecting 4\n",
            "W0317 18:54:10.833440 140450983094144 ag_logging.py:145] Entity <bound method Conv.call of <tensorflow.python.layers.convolutional.Conv2D object at 0x7fbd004f7050>> could not be transformed and will be executed as-is. Please report this to the AutgoGraph team. When filing the bug, set the verbosity to 10 (on Linux, `export AUTOGRAPH_VERBOSITY=10`) and attach the full output. Cause: converting <bound method Conv.call of <tensorflow.python.layers.convolutional.Conv2D object at 0x7fbd004f7050>>: AssertionError: Bad argument number for Name: 3, expecting 4\n",
            "WARNING:tensorflow:Entity <bound method Pooling2D.call of <tensorflow.python.layers.pooling.MaxPooling2D object at 0x7fbcff7ee1d0>> could not be transformed and will be executed as-is. Please report this to the AutgoGraph team. When filing the bug, set the verbosity to 10 (on Linux, `export AUTOGRAPH_VERBOSITY=10`) and attach the full output. Cause: converting <bound method Pooling2D.call of <tensorflow.python.layers.pooling.MaxPooling2D object at 0x7fbcff7ee1d0>>: AssertionError: Bad argument number for Name: 3, expecting 4\n",
            "W0317 18:54:10.888133 140450983094144 ag_logging.py:145] Entity <bound method Pooling2D.call of <tensorflow.python.layers.pooling.MaxPooling2D object at 0x7fbcff7ee1d0>> could not be transformed and will be executed as-is. Please report this to the AutgoGraph team. When filing the bug, set the verbosity to 10 (on Linux, `export AUTOGRAPH_VERBOSITY=10`) and attach the full output. Cause: converting <bound method Pooling2D.call of <tensorflow.python.layers.pooling.MaxPooling2D object at 0x7fbcff7ee1d0>>: AssertionError: Bad argument number for Name: 3, expecting 4\n",
            "WARNING:tensorflow:Entity <bound method Conv.call of <tensorflow.python.layers.convolutional.Conv2D object at 0x7fbcff81d3d0>> could not be transformed and will be executed as-is. Please report this to the AutgoGraph team. When filing the bug, set the verbosity to 10 (on Linux, `export AUTOGRAPH_VERBOSITY=10`) and attach the full output. Cause: converting <bound method Conv.call of <tensorflow.python.layers.convolutional.Conv2D object at 0x7fbcff81d3d0>>: AssertionError: Bad argument number for Name: 3, expecting 4\n",
            "W0317 18:54:10.973665 140450983094144 ag_logging.py:145] Entity <bound method Conv.call of <tensorflow.python.layers.convolutional.Conv2D object at 0x7fbcff81d3d0>> could not be transformed and will be executed as-is. Please report this to the AutgoGraph team. When filing the bug, set the verbosity to 10 (on Linux, `export AUTOGRAPH_VERBOSITY=10`) and attach the full output. Cause: converting <bound method Conv.call of <tensorflow.python.layers.convolutional.Conv2D object at 0x7fbcff81d3d0>>: AssertionError: Bad argument number for Name: 3, expecting 4\n",
            "WARNING:tensorflow:Entity <bound method Conv.call of <tensorflow.python.layers.convolutional.Conv2D object at 0x7fbcff797290>> could not be transformed and will be executed as-is. Please report this to the AutgoGraph team. When filing the bug, set the verbosity to 10 (on Linux, `export AUTOGRAPH_VERBOSITY=10`) and attach the full output. Cause: converting <bound method Conv.call of <tensorflow.python.layers.convolutional.Conv2D object at 0x7fbcff797290>>: AssertionError: Bad argument number for Name: 3, expecting 4\n",
            "W0317 18:54:11.057135 140450983094144 ag_logging.py:145] Entity <bound method Conv.call of <tensorflow.python.layers.convolutional.Conv2D object at 0x7fbcff797290>> could not be transformed and will be executed as-is. Please report this to the AutgoGraph team. When filing the bug, set the verbosity to 10 (on Linux, `export AUTOGRAPH_VERBOSITY=10`) and attach the full output. Cause: converting <bound method Conv.call of <tensorflow.python.layers.convolutional.Conv2D object at 0x7fbcff797290>>: AssertionError: Bad argument number for Name: 3, expecting 4\n",
            "WARNING:tensorflow:Entity <bound method Conv.call of <tensorflow.python.layers.convolutional.Conv2D object at 0x7fbd004f7310>> could not be transformed and will be executed as-is. Please report this to the AutgoGraph team. When filing the bug, set the verbosity to 10 (on Linux, `export AUTOGRAPH_VERBOSITY=10`) and attach the full output. Cause: converting <bound method Conv.call of <tensorflow.python.layers.convolutional.Conv2D object at 0x7fbd004f7310>>: AssertionError: Bad argument number for Name: 3, expecting 4\n",
            "W0317 18:54:11.140061 140450983094144 ag_logging.py:145] Entity <bound method Conv.call of <tensorflow.python.layers.convolutional.Conv2D object at 0x7fbd004f7310>> could not be transformed and will be executed as-is. Please report this to the AutgoGraph team. When filing the bug, set the verbosity to 10 (on Linux, `export AUTOGRAPH_VERBOSITY=10`) and attach the full output. Cause: converting <bound method Conv.call of <tensorflow.python.layers.convolutional.Conv2D object at 0x7fbd004f7310>>: AssertionError: Bad argument number for Name: 3, expecting 4\n",
            "WARNING:tensorflow:Entity <bound method Pooling2D.call of <tensorflow.python.layers.pooling.MaxPooling2D object at 0x7fbcff6d9650>> could not be transformed and will be executed as-is. Please report this to the AutgoGraph team. When filing the bug, set the verbosity to 10 (on Linux, `export AUTOGRAPH_VERBOSITY=10`) and attach the full output. Cause: converting <bound method Pooling2D.call of <tensorflow.python.layers.pooling.MaxPooling2D object at 0x7fbcff6d9650>>: AssertionError: Bad argument number for Name: 3, expecting 4\n",
            "W0317 18:54:11.196422 140450983094144 ag_logging.py:145] Entity <bound method Pooling2D.call of <tensorflow.python.layers.pooling.MaxPooling2D object at 0x7fbcff6d9650>> could not be transformed and will be executed as-is. Please report this to the AutgoGraph team. When filing the bug, set the verbosity to 10 (on Linux, `export AUTOGRAPH_VERBOSITY=10`) and attach the full output. Cause: converting <bound method Pooling2D.call of <tensorflow.python.layers.pooling.MaxPooling2D object at 0x7fbcff6d9650>>: AssertionError: Bad argument number for Name: 3, expecting 4\n",
            "WARNING:tensorflow:Entity <bound method Conv.call of <tensorflow.python.layers.convolutional.Conv2D object at 0x7fbcff7e6410>> could not be transformed and will be executed as-is. Please report this to the AutgoGraph team. When filing the bug, set the verbosity to 10 (on Linux, `export AUTOGRAPH_VERBOSITY=10`) and attach the full output. Cause: converting <bound method Conv.call of <tensorflow.python.layers.convolutional.Conv2D object at 0x7fbcff7e6410>>: AssertionError: Bad argument number for Name: 3, expecting 4\n",
            "W0317 18:54:11.283782 140450983094144 ag_logging.py:145] Entity <bound method Conv.call of <tensorflow.python.layers.convolutional.Conv2D object at 0x7fbcff7e6410>> could not be transformed and will be executed as-is. Please report this to the AutgoGraph team. When filing the bug, set the verbosity to 10 (on Linux, `export AUTOGRAPH_VERBOSITY=10`) and attach the full output. Cause: converting <bound method Conv.call of <tensorflow.python.layers.convolutional.Conv2D object at 0x7fbcff7e6410>>: AssertionError: Bad argument number for Name: 3, expecting 4\n",
            "WARNING:tensorflow:Entity <bound method Conv.call of <tensorflow.python.layers.convolutional.Conv2D object at 0x7fbd00562e90>> could not be transformed and will be executed as-is. Please report this to the AutgoGraph team. When filing the bug, set the verbosity to 10 (on Linux, `export AUTOGRAPH_VERBOSITY=10`) and attach the full output. Cause: converting <bound method Conv.call of <tensorflow.python.layers.convolutional.Conv2D object at 0x7fbd00562e90>>: AssertionError: Bad argument number for Name: 3, expecting 4\n",
            "W0317 18:54:11.365535 140450983094144 ag_logging.py:145] Entity <bound method Conv.call of <tensorflow.python.layers.convolutional.Conv2D object at 0x7fbd00562e90>> could not be transformed and will be executed as-is. Please report this to the AutgoGraph team. When filing the bug, set the verbosity to 10 (on Linux, `export AUTOGRAPH_VERBOSITY=10`) and attach the full output. Cause: converting <bound method Conv.call of <tensorflow.python.layers.convolutional.Conv2D object at 0x7fbd00562e90>>: AssertionError: Bad argument number for Name: 3, expecting 4\n",
            "WARNING:tensorflow:Entity <bound method Conv.call of <tensorflow.python.layers.convolutional.Conv2D object at 0x7fbd00562590>> could not be transformed and will be executed as-is. Please report this to the AutgoGraph team. When filing the bug, set the verbosity to 10 (on Linux, `export AUTOGRAPH_VERBOSITY=10`) and attach the full output. Cause: converting <bound method Conv.call of <tensorflow.python.layers.convolutional.Conv2D object at 0x7fbd00562590>>: AssertionError: Bad argument number for Name: 3, expecting 4\n",
            "W0317 18:54:11.451487 140450983094144 ag_logging.py:145] Entity <bound method Conv.call of <tensorflow.python.layers.convolutional.Conv2D object at 0x7fbd00562590>> could not be transformed and will be executed as-is. Please report this to the AutgoGraph team. When filing the bug, set the verbosity to 10 (on Linux, `export AUTOGRAPH_VERBOSITY=10`) and attach the full output. Cause: converting <bound method Conv.call of <tensorflow.python.layers.convolutional.Conv2D object at 0x7fbd00562590>>: AssertionError: Bad argument number for Name: 3, expecting 4\n",
            "WARNING:tensorflow:Entity <bound method Conv.call of <tensorflow.python.layers.convolutional.Conv2D object at 0x7fbd005695d0>> could not be transformed and will be executed as-is. Please report this to the AutgoGraph team. When filing the bug, set the verbosity to 10 (on Linux, `export AUTOGRAPH_VERBOSITY=10`) and attach the full output. Cause: converting <bound method Conv.call of <tensorflow.python.layers.convolutional.Conv2D object at 0x7fbd005695d0>>: AssertionError: Bad argument number for Name: 3, expecting 4\n",
            "W0317 18:54:11.530739 140450983094144 ag_logging.py:145] Entity <bound method Conv.call of <tensorflow.python.layers.convolutional.Conv2D object at 0x7fbd005695d0>> could not be transformed and will be executed as-is. Please report this to the AutgoGraph team. When filing the bug, set the verbosity to 10 (on Linux, `export AUTOGRAPH_VERBOSITY=10`) and attach the full output. Cause: converting <bound method Conv.call of <tensorflow.python.layers.convolutional.Conv2D object at 0x7fbd005695d0>>: AssertionError: Bad argument number for Name: 3, expecting 4\n",
            "WARNING:tensorflow:From /content/text-detection-ctpn/nets/model_train.py:30: LSTMCell.__init__ (from tensorflow.python.ops.rnn_cell_impl) is deprecated and will be removed in a future version.\n",
            "Instructions for updating:\n",
            "This class is equivalent as tf.keras.layers.LSTMCell, and will be replaced by that in Tensorflow 2.0.\n",
            "W0317 18:54:11.546492 140450983094144 deprecation.py:323] From /content/text-detection-ctpn/nets/model_train.py:30: LSTMCell.__init__ (from tensorflow.python.ops.rnn_cell_impl) is deprecated and will be removed in a future version.\n",
            "Instructions for updating:\n",
            "This class is equivalent as tf.keras.layers.LSTMCell, and will be replaced by that in Tensorflow 2.0.\n",
            "WARNING:tensorflow:From /content/text-detection-ctpn/nets/model_train.py:33: bidirectional_dynamic_rnn (from tensorflow.python.ops.rnn) is deprecated and will be removed in a future version.\n",
            "Instructions for updating:\n",
            "Please use `keras.layers.Bidirectional(keras.layers.RNN(cell))`, which is equivalent to this API\n",
            "W0317 18:54:11.547276 140450983094144 deprecation.py:323] From /content/text-detection-ctpn/nets/model_train.py:33: bidirectional_dynamic_rnn (from tensorflow.python.ops.rnn) is deprecated and will be removed in a future version.\n",
            "Instructions for updating:\n",
            "Please use `keras.layers.Bidirectional(keras.layers.RNN(cell))`, which is equivalent to this API\n",
            "WARNING:tensorflow:From /usr/local/lib/python3.7/dist-packages/tensorflow/python/ops/rnn.py:464: dynamic_rnn (from tensorflow.python.ops.rnn) is deprecated and will be removed in a future version.\n",
            "Instructions for updating:\n",
            "Please use `keras.layers.RNN(cell)`, which is equivalent to this API\n",
            "W0317 18:54:11.547700 140450983094144 deprecation.py:323] From /usr/local/lib/python3.7/dist-packages/tensorflow/python/ops/rnn.py:464: dynamic_rnn (from tensorflow.python.ops.rnn) is deprecated and will be removed in a future version.\n",
            "Instructions for updating:\n",
            "Please use `keras.layers.RNN(cell)`, which is equivalent to this API\n",
            "WARNING:tensorflow:From /usr/local/lib/python3.7/dist-packages/tensorflow/python/ops/init_ops.py:1251: calling VarianceScaling.__init__ (from tensorflow.python.ops.init_ops) with dtype is deprecated and will be removed in a future version.\n",
            "Instructions for updating:\n",
            "Call initializer instance with the dtype argument instead of passing it to the constructor\n",
            "W0317 18:54:11.611135 140450983094144 deprecation.py:506] From /usr/local/lib/python3.7/dist-packages/tensorflow/python/ops/init_ops.py:1251: calling VarianceScaling.__init__ (from tensorflow.python.ops.init_ops) with dtype is deprecated and will be removed in a future version.\n",
            "Instructions for updating:\n",
            "Call initializer instance with the dtype argument instead of passing it to the constructor\n",
            "WARNING:tensorflow:From /usr/local/lib/python3.7/dist-packages/tensorflow/python/ops/rnn_cell_impl.py:961: calling Zeros.__init__ (from tensorflow.python.ops.init_ops) with dtype is deprecated and will be removed in a future version.\n",
            "Instructions for updating:\n",
            "Call initializer instance with the dtype argument instead of passing it to the constructor\n",
            "W0317 18:54:11.621386 140450983094144 deprecation.py:506] From /usr/local/lib/python3.7/dist-packages/tensorflow/python/ops/rnn_cell_impl.py:961: calling Zeros.__init__ (from tensorflow.python.ops.init_ops) with dtype is deprecated and will be removed in a future version.\n",
            "Instructions for updating:\n",
            "Call initializer instance with the dtype argument instead of passing it to the constructor\n",
            "WARNING:tensorflow:Entity <bound method LSTMCell.call of <tensorflow.python.ops.rnn_cell_impl.LSTMCell object at 0x7fbcff78e850>> could not be transformed and will be executed as-is. Please report this to the AutgoGraph team. When filing the bug, set the verbosity to 10 (on Linux, `export AUTOGRAPH_VERBOSITY=10`) and attach the full output. Cause: converting <bound method LSTMCell.call of <tensorflow.python.ops.rnn_cell_impl.LSTMCell object at 0x7fbcff78e850>>: AttributeError: module 'gast' has no attribute 'Num'\n",
            "W0317 18:54:11.648699 140450983094144 ag_logging.py:145] Entity <bound method LSTMCell.call of <tensorflow.python.ops.rnn_cell_impl.LSTMCell object at 0x7fbcff78e850>> could not be transformed and will be executed as-is. Please report this to the AutgoGraph team. When filing the bug, set the verbosity to 10 (on Linux, `export AUTOGRAPH_VERBOSITY=10`) and attach the full output. Cause: converting <bound method LSTMCell.call of <tensorflow.python.ops.rnn_cell_impl.LSTMCell object at 0x7fbcff78e850>>: AttributeError: module 'gast' has no attribute 'Num'\n",
            "WARNING:tensorflow:Entity <bound method LSTMCell.call of <tensorflow.python.ops.rnn_cell_impl.LSTMCell object at 0x7fbd005404d0>> could not be transformed and will be executed as-is. Please report this to the AutgoGraph team. When filing the bug, set the verbosity to 10 (on Linux, `export AUTOGRAPH_VERBOSITY=10`) and attach the full output. Cause: converting <bound method LSTMCell.call of <tensorflow.python.ops.rnn_cell_impl.LSTMCell object at 0x7fbd005404d0>>: AttributeError: module 'gast' has no attribute 'Num'\n",
            "W0317 18:54:11.783532 140450983094144 ag_logging.py:145] Entity <bound method LSTMCell.call of <tensorflow.python.ops.rnn_cell_impl.LSTMCell object at 0x7fbd005404d0>> could not be transformed and will be executed as-is. Please report this to the AutgoGraph team. When filing the bug, set the verbosity to 10 (on Linux, `export AUTOGRAPH_VERBOSITY=10`) and attach the full output. Cause: converting <bound method LSTMCell.call of <tensorflow.python.ops.rnn_cell_impl.LSTMCell object at 0x7fbd005404d0>>: AttributeError: module 'gast' has no attribute 'Num'\n",
            "WARNING:tensorflow:From ./main/demo.py:69: The name tf.train.Saver is deprecated. Please use tf.compat.v1.train.Saver instead.\n",
            "\n",
            "W0317 18:54:12.027933 140450983094144 deprecation_wrapper.py:119] From ./main/demo.py:69: The name tf.train.Saver is deprecated. Please use tf.compat.v1.train.Saver instead.\n",
            "\n",
            "WARNING:tensorflow:From ./main/demo.py:71: The name tf.Session is deprecated. Please use tf.compat.v1.Session instead.\n",
            "\n",
            "W0317 18:54:12.065643 140450983094144 deprecation_wrapper.py:119] From ./main/demo.py:71: The name tf.Session is deprecated. Please use tf.compat.v1.Session instead.\n",
            "\n",
            "2021-03-17 18:54:12.066118: I tensorflow/core/platform/cpu_feature_guard.cc:142] Your CPU supports instructions that this TensorFlow binary was not compiled to use: AVX2 FMA\n",
            "2021-03-17 18:54:12.070448: I tensorflow/core/platform/profile_utils/cpu_utils.cc:94] CPU Frequency: 2299995000 Hz\n",
            "2021-03-17 18:54:12.070718: I tensorflow/compiler/xla/service/service.cc:168] XLA service 0x564d0492cc40 executing computations on platform Host. Devices:\n",
            "2021-03-17 18:54:12.070761: I tensorflow/compiler/xla/service/service.cc:175]   StreamExecutor device (0): <undefined>, <undefined>\n",
            "Restore from checkpoints_mlt/ctpn_50000.ckpt\n",
            "WARNING:tensorflow:From /usr/local/lib/python3.7/dist-packages/tensorflow/python/training/saver.py:1276: checkpoint_exists (from tensorflow.python.training.checkpoint_management) is deprecated and will be removed in a future version.\n",
            "Instructions for updating:\n",
            "Use standard file APIs to check for files with this prefix.\n",
            "W0317 18:54:12.077436 140450983094144 deprecation.py:323] From /usr/local/lib/python3.7/dist-packages/tensorflow/python/training/saver.py:1276: checkpoint_exists (from tensorflow.python.training.checkpoint_management) is deprecated and will be removed in a future version.\n",
            "Instructions for updating:\n",
            "Use standard file APIs to check for files with this prefix.\n",
            "INFO:tensorflow:Restoring parameters from checkpoints_mlt/ctpn_50000.ckpt\n",
            "I0317 18:54:12.078503 140450983094144 saver.py:1280] Restoring parameters from checkpoints_mlt/ctpn_50000.ckpt\n",
            "2021-03-17 18:54:12.124517: W tensorflow/compiler/jit/mark_for_compilation_pass.cc:1412] (One-time warning): Not using XLA:CPU for cluster because envvar TF_XLA_FLAGS=--tf_xla_cpu_global_jit was not set.  If you want XLA:CPU, either set that envvar, or use experimental_jit_scope to enable XLA:CPU.  To confirm that XLA is active, pass --vmodule=xla_compilation_cache=1 (as a proper command-line flag, not via TF_XLA_FLAGS) or set the envvar XLA_FLAGS=--xla_hlo_profile.\n",
            "Find 5 images\n",
            "===============\n",
            "data/demo/009.jpg\n",
            "tcmalloc: large alloc 1143308288 bytes == 0x564d1e628000 @  0x7fbd4ab191e7 0x7fbd281fcc05 0x7fbd28cd18fe 0x7fbd2b0ada20 0x7fbd2b6b0b00 0x7fbd2b6b20ce 0x7fbd2b722ab1 0x7fbd2b726276 0x7fbd2b726c03 0x7fbd24d03136 0x7fbd24cf35c5 0x7fbd24d9d3ae 0x7fbd24d9a228 0x7fbd493fba50 0x7fbd4a8ce6db 0x7fbd49a0371f\n",
            "cost time: 6.52s\n",
            "===============\n",
            "data/demo/010.png\n",
            "cost time: 5.59s\n",
            "===============\n",
            "data/demo/008.jpg\n",
            "cost time: 6.46s\n",
            "===============\n",
            "data/demo/006.jpg\n",
            "cost time: 6.38s\n",
            "===============\n",
            "data/demo/007.jpg\n",
            "tcmalloc: large alloc 1277788160 bytes == 0x564d2169c000 @  0x7fbd4ab191e7 0x7fbd281fcc05 0x7fbd28cd18fe 0x7fbd2b0ada20 0x7fbd2b6b0b00 0x7fbd2b6b20ce 0x7fbd2b722ab1 0x7fbd2b726276 0x7fbd2b726c03 0x7fbd24d03136 0x7fbd24cf35c5 0x7fbd24d9d3ae 0x7fbd24d9a228 0x7fbd493fba50 0x7fbd4a8ce6db 0x7fbd49a0371f\n",
            "cost time: 6.96s\n"
          ],
          "name": "stdout"
        }
      ]
    }
  ]
}